[2023-12-28T00:06:06.275+0500] {taskinstance.py:1159} INFO - Dependencies all met for dep_context=non-requeueable deps ti=<TaskInstance: KOH.data_ml manual__2023-12-27T19:05:58.656250+00:00 [queued]>
[2023-12-28T00:06:06.292+0500] {taskinstance.py:1159} INFO - Dependencies all met for dep_context=requeueable deps ti=<TaskInstance: KOH.data_ml manual__2023-12-27T19:05:58.656250+00:00 [queued]>
[2023-12-28T00:06:06.293+0500] {taskinstance.py:1361} INFO - Starting attempt 1 of 2
[2023-12-28T00:06:06.324+0500] {taskinstance.py:1382} INFO - Executing <Task(BashOperator): data_ml> on 2023-12-27 19:05:58.656250+00:00
[2023-12-28T00:06:06.331+0500] {standard_task_runner.py:57} INFO - Started process 7689 to run task
[2023-12-28T00:06:06.335+0500] {standard_task_runner.py:84} INFO - Running: ['airflow', 'tasks', 'run', 'KOH', 'data_ml', 'manual__2023-12-27T19:05:58.656250+00:00', '--job-id', '223', '--raw', '--subdir', 'DAGS_FOLDER/text.py', '--cfg-path', '/tmp/tmpxmn44ejl']
[2023-12-28T00:06:06.336+0500] {standard_task_runner.py:85} INFO - Job 223: Subtask data_ml
[2023-12-28T00:06:06.400+0500] {task_command.py:416} INFO - Running <TaskInstance: KOH.data_ml manual__2023-12-27T19:05:58.656250+00:00 [running]> on host vm2.myguest.virtualbox.org
[2023-12-28T00:06:06.523+0500] {taskinstance.py:1662} INFO - Exporting env vars: AIRFLOW_CTX_DAG_OWNER='Admin' AIRFLOW_CTX_DAG_ID='KOH' AIRFLOW_CTX_TASK_ID='data_ml' AIRFLOW_CTX_EXECUTION_DATE='2023-12-27T19:05:58.656250+00:00' AIRFLOW_CTX_TRY_NUMBER='1' AIRFLOW_CTX_DAG_RUN_ID='manual__2023-12-27T19:05:58.656250+00:00'
[2023-12-28T00:06:06.525+0500] {subprocess.py:63} INFO - Tmp dir root location: /tmp
[2023-12-28T00:06:06.526+0500] {subprocess.py:75} INFO - Running command: ['/usr/bin/bash', '-c', 'cd /home/kda/ML_lab3/MLops_lab3/ && python /home/kda/ML_lab3/MLops_lab3/scripts/model_learn.py']
[2023-12-28T00:06:06.540+0500] {subprocess.py:86} INFO - Output:
[2023-12-28T00:06:09.965+0500] {process_utils.py:131} INFO - Sending Signals.SIGTERM to group 7689. PIDs of all processes in the group: [7690, 7689]
[2023-12-28T00:06:09.965+0500] {process_utils.py:86} INFO - Sending the signal Signals.SIGTERM to group 7689
[2023-12-28T00:06:09.965+0500] {taskinstance.py:1632} ERROR - Received SIGTERM. Terminating subprocesses.
[2023-12-28T00:06:09.965+0500] {subprocess.py:104} INFO - Sending SIGTERM signal to process group
[2023-12-28T00:06:09.972+0500] {taskinstance.py:1937} ERROR - Task failed with exception
Traceback (most recent call last):
  File "/home/kda/ML_lab3/MLops_lab3/lab3/lib/python3.10/site-packages/airflow/operators/bash.py", line 201, in execute
    result = self.subprocess_hook.run_command(
  File "/home/kda/ML_lab3/MLops_lab3/lab3/lib/python3.10/site-packages/airflow/hooks/subprocess.py", line 91, in run_command
    for raw_line in iter(self.sub_process.stdout.readline, b""):
  File "/home/kda/ML_lab3/MLops_lab3/lab3/lib/python3.10/site-packages/airflow/models/taskinstance.py", line 1634, in signal_handler
    raise AirflowException("Task received SIGTERM signal")
airflow.exceptions.AirflowException: Task received SIGTERM signal
[2023-12-28T00:06:09.980+0500] {taskinstance.py:1400} INFO - Marking task as UP_FOR_RETRY. dag_id=KOH, task_id=data_ml, execution_date=20231227T190558, start_date=20231227T190606, end_date=20231227T190609
[2023-12-28T00:06:10.026+0500] {standard_task_runner.py:104} ERROR - Failed to execute job 223 for task data_ml (Task received SIGTERM signal; 7689)
[2023-12-28T00:06:10.048+0500] {process_utils.py:79} INFO - Process psutil.Process(pid=7689, status='terminated', exitcode=1, started='00:06:06') (7689) terminated with exit code 1
[2023-12-28T00:06:10.049+0500] {process_utils.py:79} INFO - Process psutil.Process(pid=7690, status='terminated', started='00:06:06') (7690) terminated with exit code None
