[2023-12-26T22:52:57.316+0500] {taskinstance.py:1159} INFO - Dependencies all met for dep_context=non-requeueable deps ti=<TaskInstance: KOH.data_ml manual__2023-12-26T17:51:45.629827+00:00 [queued]>
[2023-12-26T22:52:57.349+0500] {taskinstance.py:1159} INFO - Dependencies all met for dep_context=requeueable deps ti=<TaskInstance: KOH.data_ml manual__2023-12-26T17:51:45.629827+00:00 [queued]>
[2023-12-26T22:52:57.349+0500] {taskinstance.py:1361} INFO - Starting attempt 1 of 2
[2023-12-26T22:52:57.406+0500] {taskinstance.py:1382} INFO - Executing <Task(BashOperator): data_ml> on 2023-12-26 17:51:45.629827+00:00
[2023-12-26T22:52:57.410+0500] {standard_task_runner.py:57} INFO - Started process 11520 to run task
[2023-12-26T22:52:57.433+0500] {standard_task_runner.py:84} INFO - Running: ['airflow', 'tasks', 'run', 'KOH', 'data_ml', 'manual__2023-12-26T17:51:45.629827+00:00', '--job-id', '57', '--raw', '--subdir', 'DAGS_FOLDER/text.py', '--cfg-path', '/tmp/tmp1uqfr144']
[2023-12-26T22:52:57.436+0500] {standard_task_runner.py:85} INFO - Job 57: Subtask data_ml
[2023-12-26T22:52:57.582+0500] {task_command.py:416} INFO - Running <TaskInstance: KOH.data_ml manual__2023-12-26T17:51:45.629827+00:00 [running]> on host vm2.myguest.virtualbox.org
[2023-12-26T22:52:57.771+0500] {taskinstance.py:1662} INFO - Exporting env vars: AIRFLOW_CTX_DAG_OWNER='Admin' AIRFLOW_CTX_DAG_ID='KOH' AIRFLOW_CTX_TASK_ID='data_ml' AIRFLOW_CTX_EXECUTION_DATE='2023-12-26T17:51:45.629827+00:00' AIRFLOW_CTX_TRY_NUMBER='1' AIRFLOW_CTX_DAG_RUN_ID='manual__2023-12-26T17:51:45.629827+00:00'
[2023-12-26T22:52:57.774+0500] {subprocess.py:63} INFO - Tmp dir root location: /tmp
[2023-12-26T22:52:57.777+0500] {subprocess.py:75} INFO - Running command: ['/usr/bin/bash', '-c', 'cd /home/kda/ML_lab3/MLops_lab3/ && python /home/kda/ML_lab3/MLops_lab3/scripts/model_learn.py']
[2023-12-26T22:52:57.798+0500] {subprocess.py:86} INFO - Output:
[2023-12-26T22:52:57.859+0500] {subprocess.py:93} INFO - python: can't open file '/home/kda/ML_lab3/MLops_lab3/scripts/model_learn.py': [Errno 2] No such file or directory
[2023-12-26T22:52:57.863+0500] {subprocess.py:97} INFO - Command exited with return code 2
[2023-12-26T22:52:57.885+0500] {taskinstance.py:1937} ERROR - Task failed with exception
Traceback (most recent call last):
  File "/home/kda/ML_lab3/MLops_lab3/lab3/lib/python3.10/site-packages/airflow/operators/bash.py", line 210, in execute
    raise AirflowException(
airflow.exceptions.AirflowException: Bash command failed. The command returned a non-zero exit code 2.
[2023-12-26T22:52:57.906+0500] {taskinstance.py:1400} INFO - Marking task as UP_FOR_RETRY. dag_id=KOH, task_id=data_ml, execution_date=20231226T175145, start_date=20231226T175257, end_date=20231226T175257
[2023-12-26T22:52:57.956+0500] {standard_task_runner.py:104} ERROR - Failed to execute job 57 for task data_ml (Bash command failed. The command returned a non-zero exit code 2.; 11520)
[2023-12-26T22:52:57.978+0500] {local_task_job_runner.py:228} INFO - Task exited with return code 1
[2023-12-26T22:52:58.007+0500] {taskinstance.py:2778} INFO - 0 downstream tasks scheduled from follow-on schedule check
