[2023-12-10T17:45:38.418+0500] {taskinstance.py:1159} INFO - Dependencies all met for dep_context=non-requeueable deps ti=<TaskInstance: KOH.data_2 manual__2023-12-10T12:45:22.967673+00:00 [queued]>
[2023-12-10T17:45:38.473+0500] {taskinstance.py:1159} INFO - Dependencies all met for dep_context=requeueable deps ti=<TaskInstance: KOH.data_2 manual__2023-12-10T12:45:22.967673+00:00 [queued]>
[2023-12-10T17:45:38.473+0500] {taskinstance.py:1361} INFO - Starting attempt 1 of 2
[2023-12-10T17:45:38.578+0500] {taskinstance.py:1382} INFO - Executing <Task(BashOperator): data_2> on 2023-12-10 12:45:22.967673+00:00
[2023-12-10T17:45:38.615+0500] {standard_task_runner.py:57} INFO - Started process 5045 to run task
[2023-12-10T17:45:38.621+0500] {standard_task_runner.py:84} INFO - Running: ['airflow', 'tasks', 'run', 'KOH', 'data_2', 'manual__2023-12-10T12:45:22.967673+00:00', '--job-id', '11', '--raw', '--subdir', 'DAGS_FOLDER/text.py', '--cfg-path', '/tmp/tmpchoz7bkh']
[2023-12-10T17:45:38.627+0500] {standard_task_runner.py:85} INFO - Job 11: Subtask data_2
[2023-12-10T17:45:38.769+0500] {task_command.py:416} INFO - Running <TaskInstance: KOH.data_2 manual__2023-12-10T12:45:22.967673+00:00 [running]> on host vm2.myguest.virtualbox.org
[2023-12-10T17:45:38.945+0500] {taskinstance.py:1662} INFO - Exporting env vars: AIRFLOW_CTX_DAG_OWNER='Admin' AIRFLOW_CTX_DAG_ID='KOH' AIRFLOW_CTX_TASK_ID='data_2' AIRFLOW_CTX_EXECUTION_DATE='2023-12-10T12:45:22.967673+00:00' AIRFLOW_CTX_TRY_NUMBER='1' AIRFLOW_CTX_DAG_RUN_ID='manual__2023-12-10T12:45:22.967673+00:00'
[2023-12-10T17:45:38.946+0500] {subprocess.py:63} INFO - Tmp dir root location: /tmp
[2023-12-10T17:45:38.948+0500] {subprocess.py:75} INFO - Running command: ['/usr/bin/bash', '-c', 'python /home/kda/ML_lab3/MLops_lab3/scripts/script2.py']
[2023-12-10T17:45:38.966+0500] {subprocess.py:86} INFO - Output:
[2023-12-10T17:45:40.420+0500] {subprocess.py:93} INFO - Traceback (most recent call last):
[2023-12-10T17:45:40.422+0500] {subprocess.py:93} INFO -   File "/home/kda/ML_lab3/MLops_lab3/scripts/script2.py", line 8, in <module>
[2023-12-10T17:45:40.423+0500] {subprocess.py:93} INFO -     scp = pd.read_csv("/home/kda/ML_lab3/MLops_lab3/datasets/stage1/Sport_car_price.csv")
[2023-12-10T17:45:40.423+0500] {subprocess.py:93} INFO -   File "/home/kda/ML_lab3/MLops_lab3/lab3/lib/python3.10/site-packages/pandas/io/parsers/readers.py", line 948, in read_csv
[2023-12-10T17:45:40.424+0500] {subprocess.py:93} INFO -     return _read(filepath_or_buffer, kwds)
[2023-12-10T17:45:40.425+0500] {subprocess.py:93} INFO -   File "/home/kda/ML_lab3/MLops_lab3/lab3/lib/python3.10/site-packages/pandas/io/parsers/readers.py", line 611, in _read
[2023-12-10T17:45:40.426+0500] {subprocess.py:93} INFO -     parser = TextFileReader(filepath_or_buffer, **kwds)
[2023-12-10T17:45:40.426+0500] {subprocess.py:93} INFO -   File "/home/kda/ML_lab3/MLops_lab3/lab3/lib/python3.10/site-packages/pandas/io/parsers/readers.py", line 1448, in __init__
[2023-12-10T17:45:40.427+0500] {subprocess.py:93} INFO -     self._engine = self._make_engine(f, self.engine)
[2023-12-10T17:45:40.427+0500] {subprocess.py:93} INFO -   File "/home/kda/ML_lab3/MLops_lab3/lab3/lib/python3.10/site-packages/pandas/io/parsers/readers.py", line 1705, in _make_engine
[2023-12-10T17:45:40.427+0500] {subprocess.py:93} INFO -     self.handles = get_handle(
[2023-12-10T17:45:40.427+0500] {subprocess.py:93} INFO -   File "/home/kda/ML_lab3/MLops_lab3/lab3/lib/python3.10/site-packages/pandas/io/common.py", line 863, in get_handle
[2023-12-10T17:45:40.427+0500] {subprocess.py:93} INFO -     handle = open(
[2023-12-10T17:45:40.428+0500] {subprocess.py:93} INFO - FileNotFoundError: [Errno 2] No such file or directory: '/home/kda/ML_lab3/MLops_lab3/datasets/stage1/Sport_car_price.csv'
[2023-12-10T17:45:40.609+0500] {subprocess.py:97} INFO - Command exited with return code 1
[2023-12-10T17:45:40.624+0500] {taskinstance.py:1937} ERROR - Task failed with exception
Traceback (most recent call last):
  File "/home/kda/ML_lab3/MLops_lab3/lab3/lib/python3.10/site-packages/airflow/operators/bash.py", line 210, in execute
    raise AirflowException(
airflow.exceptions.AirflowException: Bash command failed. The command returned a non-zero exit code 1.
[2023-12-10T17:45:40.636+0500] {taskinstance.py:1400} INFO - Marking task as UP_FOR_RETRY. dag_id=KOH, task_id=data_2, execution_date=20231210T124522, start_date=20231210T124538, end_date=20231210T124540
[2023-12-10T17:45:40.677+0500] {standard_task_runner.py:104} ERROR - Failed to execute job 11 for task data_2 (Bash command failed. The command returned a non-zero exit code 1.; 5045)
[2023-12-10T17:45:40.697+0500] {local_task_job_runner.py:228} INFO - Task exited with return code 1
[2023-12-10T17:45:40.719+0500] {taskinstance.py:2778} INFO - 0 downstream tasks scheduled from follow-on schedule check
