[2023-12-30T17:28:50.656+0500] {taskinstance.py:1159} INFO - Dependencies all met for dep_context=non-requeueable deps ti=<TaskInstance: KOH.evaluate manual__2023-12-30T12:26:39.265435+00:00 [queued]>
[2023-12-30T17:28:50.667+0500] {taskinstance.py:1159} INFO - Dependencies all met for dep_context=requeueable deps ti=<TaskInstance: KOH.evaluate manual__2023-12-30T12:26:39.265435+00:00 [queued]>
[2023-12-30T17:28:50.667+0500] {taskinstance.py:1361} INFO - Starting attempt 1 of 2
[2023-12-30T17:28:50.687+0500] {taskinstance.py:1382} INFO - Executing <Task(BashOperator): evaluate> on 2023-12-30 12:26:39.265435+00:00
[2023-12-30T17:28:50.692+0500] {standard_task_runner.py:57} INFO - Started process 22090 to run task
[2023-12-30T17:28:50.697+0500] {standard_task_runner.py:84} INFO - Running: ['airflow', 'tasks', 'run', 'KOH', 'evaluate', 'manual__2023-12-30T12:26:39.265435+00:00', '--job-id', '342', '--raw', '--subdir', 'DAGS_FOLDER/text.py', '--cfg-path', '/tmp/tmpakrw_n0b']
[2023-12-30T17:28:50.698+0500] {standard_task_runner.py:85} INFO - Job 342: Subtask evaluate
[2023-12-30T17:28:50.754+0500] {task_command.py:416} INFO - Running <TaskInstance: KOH.evaluate manual__2023-12-30T12:26:39.265435+00:00 [running]> on host vm2.myguest.virtualbox.org
[2023-12-30T17:28:50.856+0500] {taskinstance.py:1662} INFO - Exporting env vars: AIRFLOW_CTX_DAG_OWNER='Admin' AIRFLOW_CTX_DAG_ID='KOH' AIRFLOW_CTX_TASK_ID='evaluate' AIRFLOW_CTX_EXECUTION_DATE='2023-12-30T12:26:39.265435+00:00' AIRFLOW_CTX_TRY_NUMBER='1' AIRFLOW_CTX_DAG_RUN_ID='manual__2023-12-30T12:26:39.265435+00:00'
[2023-12-30T17:28:50.857+0500] {subprocess.py:63} INFO - Tmp dir root location: /tmp
[2023-12-30T17:28:50.862+0500] {subprocess.py:75} INFO - Running command: ['/usr/bin/bash', '-c', 'cd /home/kda/ML_lab3/MLops_lab3/ && python /home/kda/ML_lab3/MLops_lab3/scripts/evaluate.py']
[2023-12-30T17:28:50.884+0500] {subprocess.py:86} INFO - Output:
[2023-12-30T17:28:53.627+0500] {subprocess.py:93} INFO - Traceback (most recent call last):
[2023-12-30T17:28:53.628+0500] {subprocess.py:93} INFO -   File "/home/kda/ML_lab3/MLops_lab3/scripts/evaluate.py", line 35, in <module>
[2023-12-30T17:28:53.628+0500] {subprocess.py:93} INFO -     df_scp = pd.read_csv(test_file)
[2023-12-30T17:28:53.628+0500] {subprocess.py:93} INFO -   File "/home/kda/ML_lab3/MLops_lab3/lab3/lib/python3.10/site-packages/pandas/io/parsers/readers.py", line 948, in read_csv
[2023-12-30T17:28:53.641+0500] {subprocess.py:93} INFO -     return _read(filepath_or_buffer, kwds)
[2023-12-30T17:28:53.643+0500] {subprocess.py:93} INFO -   File "/home/kda/ML_lab3/MLops_lab3/lab3/lib/python3.10/site-packages/pandas/io/parsers/readers.py", line 611, in _read
[2023-12-30T17:28:53.645+0500] {subprocess.py:93} INFO -     parser = TextFileReader(filepath_or_buffer, **kwds)
[2023-12-30T17:28:53.646+0500] {subprocess.py:93} INFO -   File "/home/kda/ML_lab3/MLops_lab3/lab3/lib/python3.10/site-packages/pandas/io/parsers/readers.py", line 1448, in __init__
[2023-12-30T17:28:53.646+0500] {subprocess.py:93} INFO -     self._engine = self._make_engine(f, self.engine)
[2023-12-30T17:28:53.646+0500] {subprocess.py:93} INFO -   File "/home/kda/ML_lab3/MLops_lab3/lab3/lib/python3.10/site-packages/pandas/io/parsers/readers.py", line 1705, in _make_engine
[2023-12-30T17:28:53.646+0500] {subprocess.py:93} INFO -     self.handles = get_handle(
[2023-12-30T17:28:53.646+0500] {subprocess.py:93} INFO -   File "/home/kda/ML_lab3/MLops_lab3/lab3/lib/python3.10/site-packages/pandas/io/common.py", line 863, in get_handle
[2023-12-30T17:28:53.647+0500] {subprocess.py:93} INFO -     handle = open(
[2023-12-30T17:28:53.648+0500] {subprocess.py:93} INFO - FileNotFoundError: [Errno 2] No such file or directory: 'data/stage4/test.csv'
[2023-12-30T17:28:54.145+0500] {subprocess.py:97} INFO - Command exited with return code 1
[2023-12-30T17:28:54.152+0500] {taskinstance.py:1937} ERROR - Task failed with exception
Traceback (most recent call last):
  File "/home/kda/ML_lab3/MLops_lab3/lab3/lib/python3.10/site-packages/airflow/operators/bash.py", line 210, in execute
    raise AirflowException(
airflow.exceptions.AirflowException: Bash command failed. The command returned a non-zero exit code 1.
[2023-12-30T17:28:54.155+0500] {taskinstance.py:1400} INFO - Marking task as UP_FOR_RETRY. dag_id=KOH, task_id=evaluate, execution_date=20231230T122639, start_date=20231230T122850, end_date=20231230T122854
[2023-12-30T17:28:54.215+0500] {standard_task_runner.py:104} ERROR - Failed to execute job 342 for task evaluate (Bash command failed. The command returned a non-zero exit code 1.; 22090)
[2023-12-30T17:28:54.262+0500] {local_task_job_runner.py:228} INFO - Task exited with return code 1
[2023-12-30T17:28:54.278+0500] {taskinstance.py:2778} INFO - 0 downstream tasks scheduled from follow-on schedule check
