[2023-12-10T17:36:45.111+0500] {taskinstance.py:1159} INFO - Dependencies all met for dep_context=non-requeueable deps ti=<TaskInstance: KOH.data_2 manual__2023-12-10T12:36:22.639591+00:00 [queued]>
[2023-12-10T17:36:45.136+0500] {taskinstance.py:1159} INFO - Dependencies all met for dep_context=requeueable deps ti=<TaskInstance: KOH.data_2 manual__2023-12-10T12:36:22.639591+00:00 [queued]>
[2023-12-10T17:36:45.137+0500] {taskinstance.py:1361} INFO - Starting attempt 1 of 2
[2023-12-10T17:36:45.220+0500] {taskinstance.py:1382} INFO - Executing <Task(BashOperator): data_2> on 2023-12-10 12:36:22.639591+00:00
[2023-12-10T17:36:45.239+0500] {standard_task_runner.py:57} INFO - Started process 4924 to run task
[2023-12-10T17:36:45.246+0500] {standard_task_runner.py:84} INFO - Running: ['airflow', 'tasks', 'run', 'KOH', 'data_2', 'manual__2023-12-10T12:36:22.639591+00:00', '--job-id', '7', '--raw', '--subdir', 'DAGS_FOLDER/text.py', '--cfg-path', '/tmp/tmp8mdv7vm9']
[2023-12-10T17:36:45.248+0500] {standard_task_runner.py:85} INFO - Job 7: Subtask data_2
[2023-12-10T17:36:45.492+0500] {task_command.py:416} INFO - Running <TaskInstance: KOH.data_2 manual__2023-12-10T12:36:22.639591+00:00 [running]> on host vm2.myguest.virtualbox.org
[2023-12-10T17:36:45.609+0500] {taskinstance.py:1662} INFO - Exporting env vars: AIRFLOW_CTX_DAG_OWNER='Admin' AIRFLOW_CTX_DAG_ID='KOH' AIRFLOW_CTX_TASK_ID='data_2' AIRFLOW_CTX_EXECUTION_DATE='2023-12-10T12:36:22.639591+00:00' AIRFLOW_CTX_TRY_NUMBER='1' AIRFLOW_CTX_DAG_RUN_ID='manual__2023-12-10T12:36:22.639591+00:00'
[2023-12-10T17:36:45.612+0500] {subprocess.py:63} INFO - Tmp dir root location: /tmp
[2023-12-10T17:36:45.612+0500] {subprocess.py:75} INFO - Running command: ['/usr/bin/bash', '-c', 'python /home/kda/ML_lab3/MLops_lab3/scripts/script2.py']
[2023-12-10T17:36:45.642+0500] {subprocess.py:86} INFO - Output:
[2023-12-10T17:36:47.296+0500] {subprocess.py:93} INFO - Traceback (most recent call last):
[2023-12-10T17:36:47.296+0500] {subprocess.py:93} INFO -   File "/home/kda/ML_lab3/MLops_lab3/scripts/script2.py", line 8, in <module>
[2023-12-10T17:36:47.297+0500] {subprocess.py:93} INFO -     scp = pd.read_csv("/home/kda/ML_lab3/MLops_lab3/datasets/stage1/Sport car price.csv")
[2023-12-10T17:36:47.298+0500] {subprocess.py:93} INFO -   File "/home/kda/ML_lab3/MLops_lab3/lab3/lib/python3.10/site-packages/pandas/io/parsers/readers.py", line 948, in read_csv
[2023-12-10T17:36:47.314+0500] {subprocess.py:93} INFO -     return _read(filepath_or_buffer, kwds)
[2023-12-10T17:36:47.318+0500] {subprocess.py:93} INFO -   File "/home/kda/ML_lab3/MLops_lab3/lab3/lib/python3.10/site-packages/pandas/io/parsers/readers.py", line 611, in _read
[2023-12-10T17:36:47.319+0500] {subprocess.py:93} INFO -     parser = TextFileReader(filepath_or_buffer, **kwds)
[2023-12-10T17:36:47.319+0500] {subprocess.py:93} INFO -   File "/home/kda/ML_lab3/MLops_lab3/lab3/lib/python3.10/site-packages/pandas/io/parsers/readers.py", line 1448, in __init__
[2023-12-10T17:36:47.319+0500] {subprocess.py:93} INFO -     self._engine = self._make_engine(f, self.engine)
[2023-12-10T17:36:47.319+0500] {subprocess.py:93} INFO -   File "/home/kda/ML_lab3/MLops_lab3/lab3/lib/python3.10/site-packages/pandas/io/parsers/readers.py", line 1705, in _make_engine
[2023-12-10T17:36:47.320+0500] {subprocess.py:93} INFO -     self.handles = get_handle(
[2023-12-10T17:36:47.320+0500] {subprocess.py:93} INFO -   File "/home/kda/ML_lab3/MLops_lab3/lab3/lib/python3.10/site-packages/pandas/io/common.py", line 863, in get_handle
[2023-12-10T17:36:47.329+0500] {subprocess.py:93} INFO -     handle = open(
[2023-12-10T17:36:47.330+0500] {subprocess.py:93} INFO - FileNotFoundError: [Errno 2] No such file or directory: '/home/kda/ML_lab3/MLops_lab3/datasets/stage1/Sport car price.csv'
[2023-12-10T17:36:47.568+0500] {subprocess.py:97} INFO - Command exited with return code 1
[2023-12-10T17:36:47.583+0500] {taskinstance.py:1937} ERROR - Task failed with exception
Traceback (most recent call last):
  File "/home/kda/ML_lab3/MLops_lab3/lab3/lib/python3.10/site-packages/airflow/operators/bash.py", line 210, in execute
    raise AirflowException(
airflow.exceptions.AirflowException: Bash command failed. The command returned a non-zero exit code 1.
[2023-12-10T17:36:47.607+0500] {taskinstance.py:1400} INFO - Marking task as UP_FOR_RETRY. dag_id=KOH, task_id=data_2, execution_date=20231210T123622, start_date=20231210T123645, end_date=20231210T123647
[2023-12-10T17:36:47.631+0500] {standard_task_runner.py:104} ERROR - Failed to execute job 7 for task data_2 (Bash command failed. The command returned a non-zero exit code 1.; 4924)
[2023-12-10T17:36:47.644+0500] {local_task_job_runner.py:228} INFO - Task exited with return code 1
[2023-12-10T17:36:47.664+0500] {taskinstance.py:2778} INFO - 0 downstream tasks scheduled from follow-on schedule check
