[2023-12-26T23:26:29.676+0500] {taskinstance.py:1159} INFO - Dependencies all met for dep_context=non-requeueable deps ti=<TaskInstance: KOH.data_ml manual__2023-12-26T18:26:05.966753+00:00 [queued]>
[2023-12-26T23:26:29.682+0500] {taskinstance.py:1159} INFO - Dependencies all met for dep_context=requeueable deps ti=<TaskInstance: KOH.data_ml manual__2023-12-26T18:26:05.966753+00:00 [queued]>
[2023-12-26T23:26:29.683+0500] {taskinstance.py:1361} INFO - Starting attempt 1 of 2
[2023-12-26T23:26:29.730+0500] {taskinstance.py:1382} INFO - Executing <Task(BashOperator): data_ml> on 2023-12-26 18:26:05.966753+00:00
[2023-12-26T23:26:29.734+0500] {standard_task_runner.py:57} INFO - Started process 12458 to run task
[2023-12-26T23:26:29.738+0500] {standard_task_runner.py:84} INFO - Running: ['airflow', 'tasks', 'run', 'KOH', 'data_ml', 'manual__2023-12-26T18:26:05.966753+00:00', '--job-id', '101', '--raw', '--subdir', 'DAGS_FOLDER/text.py', '--cfg-path', '/tmp/tmpc7kpao8v']
[2023-12-26T23:26:29.741+0500] {standard_task_runner.py:85} INFO - Job 101: Subtask data_ml
[2023-12-26T23:26:29.780+0500] {task_command.py:416} INFO - Running <TaskInstance: KOH.data_ml manual__2023-12-26T18:26:05.966753+00:00 [running]> on host vm2.myguest.virtualbox.org
[2023-12-26T23:26:29.871+0500] {taskinstance.py:1662} INFO - Exporting env vars: AIRFLOW_CTX_DAG_OWNER='Admin' AIRFLOW_CTX_DAG_ID='KOH' AIRFLOW_CTX_TASK_ID='data_ml' AIRFLOW_CTX_EXECUTION_DATE='2023-12-26T18:26:05.966753+00:00' AIRFLOW_CTX_TRY_NUMBER='1' AIRFLOW_CTX_DAG_RUN_ID='manual__2023-12-26T18:26:05.966753+00:00'
[2023-12-26T23:26:29.872+0500] {subprocess.py:63} INFO - Tmp dir root location: /tmp
[2023-12-26T23:26:29.872+0500] {subprocess.py:75} INFO - Running command: ['/usr/bin/bash', '-c', 'cd /home/kda/ML_lab3/MLops_lab3/ && python /home/kda/ML_lab3/MLops_lab3/scripts/model_learn.py']
[2023-12-26T23:26:29.883+0500] {subprocess.py:86} INFO - Output:
[2023-12-26T23:26:45.328+0500] {job.py:219} ERROR - Job heartbeat got an exception
Traceback (most recent call last):
  File "/home/kda/ML_lab3/MLops_lab3/lab3/lib/python3.10/site-packages/sqlalchemy/engine/base.py", line 1910, in _execute_context
    self.dialect.do_execute(
  File "/home/kda/ML_lab3/MLops_lab3/lab3/lib/python3.10/site-packages/sqlalchemy/engine/default.py", line 736, in do_execute
    cursor.execute(statement, parameters)
sqlite3.OperationalError: database is locked

The above exception was the direct cause of the following exception:

Traceback (most recent call last):
  File "/home/kda/ML_lab3/MLops_lab3/lab3/lib/python3.10/site-packages/airflow/jobs/job.py", line 190, in heartbeat
    session.merge(self)
  File "/home/kda/ML_lab3/MLops_lab3/lab3/lib/python3.10/site-packages/sqlalchemy/orm/session.py", line 3056, in merge
    return self._merge(
  File "/home/kda/ML_lab3/MLops_lab3/lab3/lib/python3.10/site-packages/sqlalchemy/orm/session.py", line 3136, in _merge
    merged = self.get(
  File "/home/kda/ML_lab3/MLops_lab3/lab3/lib/python3.10/site-packages/sqlalchemy/orm/session.py", line 2853, in get
    return self._get_impl(
  File "/home/kda/ML_lab3/MLops_lab3/lab3/lib/python3.10/site-packages/sqlalchemy/orm/session.py", line 2975, in _get_impl
    return db_load_fn(
  File "/home/kda/ML_lab3/MLops_lab3/lab3/lib/python3.10/site-packages/sqlalchemy/orm/loading.py", line 530, in load_on_pk_identity
    session.execute(
  File "/home/kda/ML_lab3/MLops_lab3/lab3/lib/python3.10/site-packages/sqlalchemy/orm/session.py", line 1717, in execute
    result = conn._execute_20(statement, params or {}, execution_options)
  File "/home/kda/ML_lab3/MLops_lab3/lab3/lib/python3.10/site-packages/sqlalchemy/engine/base.py", line 1710, in _execute_20
    return meth(self, args_10style, kwargs_10style, execution_options)
  File "/home/kda/ML_lab3/MLops_lab3/lab3/lib/python3.10/site-packages/sqlalchemy/sql/elements.py", line 334, in _execute_on_connection
    return connection._execute_clauseelement(
  File "/home/kda/ML_lab3/MLops_lab3/lab3/lib/python3.10/site-packages/sqlalchemy/engine/base.py", line 1577, in _execute_clauseelement
    ret = self._execute_context(
  File "/home/kda/ML_lab3/MLops_lab3/lab3/lib/python3.10/site-packages/sqlalchemy/engine/base.py", line 1953, in _execute_context
    self._handle_dbapi_exception(
  File "/home/kda/ML_lab3/MLops_lab3/lab3/lib/python3.10/site-packages/sqlalchemy/engine/base.py", line 2134, in _handle_dbapi_exception
    util.raise_(
  File "/home/kda/ML_lab3/MLops_lab3/lab3/lib/python3.10/site-packages/sqlalchemy/util/compat.py", line 211, in raise_
    raise exception
  File "/home/kda/ML_lab3/MLops_lab3/lab3/lib/python3.10/site-packages/sqlalchemy/engine/base.py", line 1910, in _execute_context
    self.dialect.do_execute(
  File "/home/kda/ML_lab3/MLops_lab3/lab3/lib/python3.10/site-packages/sqlalchemy/engine/default.py", line 736, in do_execute
    cursor.execute(statement, parameters)
sqlalchemy.exc.OperationalError: (sqlite3.OperationalError) database is locked
[SQL: SELECT job.id AS job_id, job.dag_id AS job_dag_id, job.state AS job_state, job.job_type AS job_job_type, job.start_date AS job_start_date, job.end_date AS job_end_date, job.latest_heartbeat AS job_latest_heartbeat, job.executor_class AS job_executor_class, job.hostname AS job_hostname, job.unixname AS job_unixname 
FROM job 
WHERE job.id = ?]
[parameters: (101,)]
(Background on this error at: https://sqlalche.me/e/14/e3q8)
[2023-12-26T23:26:52.430+0500] {subprocess.py:93} INFO - Registered model 'lr' already exists. Creating a new version of this model...
[2023-12-26T23:26:52.614+0500] {subprocess.py:93} INFO - 2023/12/26 23:26:52 INFO mlflow.store.model_registry.abstract_store: Waiting up to 300 seconds for model version to finish creation. Model name: lr, version 10
[2023-12-26T23:26:52.614+0500] {subprocess.py:93} INFO - Created version '10' of model 'lr'.
[2023-12-26T23:26:52.854+0500] {subprocess.py:93} INFO - <class 'pandas.core.frame.DataFrame'>
[2023-12-26T23:26:52.854+0500] {subprocess.py:93} INFO - RangeIndex: 704 entries, 0 to 703
[2023-12-26T23:26:52.855+0500] {subprocess.py:93} INFO - Columns: 220 entries, Price (in USD) to i8
[2023-12-26T23:26:52.855+0500] {subprocess.py:93} INFO - dtypes: bool(212), float64(2), int64(6)
[2023-12-26T23:26:52.855+0500] {subprocess.py:93} INFO - memory usage: 189.9 KB
[2023-12-26T23:26:54.066+0500] {subprocess.py:97} INFO - Command exited with return code 0
[2023-12-26T23:26:54.163+0500] {taskinstance.py:1400} INFO - Marking task as SUCCESS. dag_id=KOH, task_id=data_ml, execution_date=20231226T182605, start_date=20231226T182629, end_date=20231226T182654
[2023-12-26T23:26:54.275+0500] {local_task_job_runner.py:228} INFO - Task exited with return code 0
[2023-12-26T23:26:54.326+0500] {taskinstance.py:2778} INFO - 0 downstream tasks scheduled from follow-on schedule check
