[2023-12-30T13:25:38.859+0500] {taskinstance.py:1159} INFO - Dependencies all met for dep_context=non-requeueable deps ti=<TaskInstance: KOH.data_ml manual__2023-12-30T08:25:10.090806+00:00 [queued]>
[2023-12-30T13:25:38.865+0500] {taskinstance.py:1159} INFO - Dependencies all met for dep_context=requeueable deps ti=<TaskInstance: KOH.data_ml manual__2023-12-30T08:25:10.090806+00:00 [queued]>
[2023-12-30T13:25:38.865+0500] {taskinstance.py:1361} INFO - Starting attempt 1 of 2
[2023-12-30T13:25:38.898+0500] {taskinstance.py:1382} INFO - Executing <Task(BashOperator): data_ml> on 2023-12-30 08:25:10.090806+00:00
[2023-12-30T13:25:38.904+0500] {standard_task_runner.py:57} INFO - Started process 20418 to run task
[2023-12-30T13:25:38.909+0500] {standard_task_runner.py:84} INFO - Running: ['airflow', 'tasks', 'run', 'KOH', 'data_ml', 'manual__2023-12-30T08:25:10.090806+00:00', '--job-id', '326', '--raw', '--subdir', 'DAGS_FOLDER/text.py', '--cfg-path', '/tmp/tmpfmz2r8kx']
[2023-12-30T13:25:38.910+0500] {standard_task_runner.py:85} INFO - Job 326: Subtask data_ml
[2023-12-30T13:25:39.014+0500] {task_command.py:416} INFO - Running <TaskInstance: KOH.data_ml manual__2023-12-30T08:25:10.090806+00:00 [running]> on host vm2.myguest.virtualbox.org
[2023-12-30T13:25:39.148+0500] {taskinstance.py:1662} INFO - Exporting env vars: AIRFLOW_CTX_DAG_OWNER='Admin' AIRFLOW_CTX_DAG_ID='KOH' AIRFLOW_CTX_TASK_ID='data_ml' AIRFLOW_CTX_EXECUTION_DATE='2023-12-30T08:25:10.090806+00:00' AIRFLOW_CTX_TRY_NUMBER='1' AIRFLOW_CTX_DAG_RUN_ID='manual__2023-12-30T08:25:10.090806+00:00'
[2023-12-30T13:25:39.149+0500] {subprocess.py:63} INFO - Tmp dir root location: /tmp
[2023-12-30T13:25:39.150+0500] {subprocess.py:75} INFO - Running command: ['/usr/bin/bash', '-c', 'cd /home/kda/ML_lab3/MLops_lab3/ && python /home/kda/ML_lab3/MLops_lab3/scripts/model_learn.py']
[2023-12-30T13:25:39.164+0500] {subprocess.py:86} INFO - Output:
[2023-12-30T13:25:42.160+0500] {subprocess.py:93} INFO - Traceback (most recent call last):
[2023-12-30T13:25:42.160+0500] {subprocess.py:93} INFO -   File "/home/kda/ML_lab3/MLops_lab3/scripts/model_learn.py", line 15, in <module>
[2023-12-30T13:25:42.160+0500] {subprocess.py:93} INFO -     os.makedirs(dir_path,exist_ok=True)
[2023-12-30T13:25:42.160+0500] {subprocess.py:93} INFO -   File "/usr/lib/python3.10/os.py", line 225, in makedirs
[2023-12-30T13:25:42.160+0500] {subprocess.py:93} INFO -     mkdir(name, mode)
[2023-12-30T13:25:42.160+0500] {subprocess.py:93} INFO - FileExistsError: [Errno 17] File exists: '/home/kda/ML_lab3/MLops_lab3/datasets/models/model.pkl'
[2023-12-30T13:25:42.584+0500] {subprocess.py:97} INFO - Command exited with return code 1
[2023-12-30T13:25:42.595+0500] {taskinstance.py:1937} ERROR - Task failed with exception
Traceback (most recent call last):
  File "/home/kda/ML_lab3/MLops_lab3/lab3/lib/python3.10/site-packages/airflow/operators/bash.py", line 210, in execute
    raise AirflowException(
airflow.exceptions.AirflowException: Bash command failed. The command returned a non-zero exit code 1.
[2023-12-30T13:25:42.601+0500] {taskinstance.py:1400} INFO - Marking task as UP_FOR_RETRY. dag_id=KOH, task_id=data_ml, execution_date=20231230T082510, start_date=20231230T082538, end_date=20231230T082542
[2023-12-30T13:25:42.662+0500] {standard_task_runner.py:104} ERROR - Failed to execute job 326 for task data_ml (Bash command failed. The command returned a non-zero exit code 1.; 20418)
[2023-12-30T13:25:42.677+0500] {local_task_job_runner.py:228} INFO - Task exited with return code 1
[2023-12-30T13:25:42.709+0500] {taskinstance.py:2778} INFO - 0 downstream tasks scheduled from follow-on schedule check
